Workbook

Sheet Pest Single Acquisition
A2: x | B2: G&B Model - Pest Single Acquisition Base Case
B4: Instructions
B5: 1. Fill out historical Revenue and EBITDA. Project Revenue and EBITDA for the 5 year period.
B6: 2. Fill out the transaction assumptions with TEV & leverage and other key structure information.
B7: 3. Adjust the remaining assumptions in the yellow boxes for the cash flow statement and debt schedule as appropriate.
B8: 4. Check the "check" to make sure your business has the cash flow profile to support your capital structure.
B9: 5. Modify the deal structure and exit assumptions if needed. Note: If the model is getting errors, turn the circuit breaker to 0 and back to 1.
B10: 6. Evaluate the returns.
B12: $000s unless otherwise indicated | L12: Check | N12: =IF(SUM(F67:J67)>0,"Cash Shortfall","OK") | O12: *Check here to make sure your business has enough cash flow to support the capital structure.
A14: x | B14: Sources | G14: Uses | L14: Transaction Assumptions
C15: Amount | D15: =CONCATENATE("x",$N$16) | E15: % of Total | H15: Amount | I15: =CONCATENATE("x",$N$16) | J15: % of Total | L15: TEV | N15: 2500 | O15: *Refer to the Search Fund Study to understand median multiples, revenue, EBITDA, and more.
B16: Term Debt | C16: =D16*N17 | D16: =N20 | E16: =C16/C25 | G16: TEV | H16: =N15 | I16: =H16/$N$17 | J16: =H16/$H$25 | L16: Entry Multiple | N16: EBITDA
B17: Seller Debt | C17: =N21 | D17: =C17/$N$17 | E17: =C17/C25 | G17: Fees | H17: =H16*N19 | I17: =H17/$N$17 | J17: =H17/$H$25 | L17: =IF(N16="ARR","Ending ARR","LTM EBITDA") | N17: =IF(N16="ARR",E34,E40)
B18: Total Debt | C18: =SUM(C16:C17) | D18: =C18/$N$17 | E18: =C18/$C$25 | G18: Cash to B/S | H18: =N22 | I18: =H18/$N$17 | J18: =H18/$H$25 | L18: LTM Period | N18: 2026-12-31 | O18: 2024 Search Fund Study | Stanford Graduate School of Business
L19: Transaction Costs | N19: 0.05
B20: Equity | D20: % of Equity | L20: =CONCATENATE("Term Debt x",N16) | N20: 0
B21: Seller Equity Rollover | C21: =D21*C23 | D21: =N25 | E21: =C21/C25 | L21: Seller Debt Quantum | N21: 750
B22: Investor Equity | C22: =D22*C23 | D22: =1-D21 | E22: =C22/C25 | L22: Cash to B/S | N22: 200 | O22: *Typically, searcher(s) put de minimis cash on the balance sheet.
B23: Total Equity | C23: =C25-C18 | D23: =SUM(C21:C22)/C23 | E23: =C23/C25 | L23: ECF Distribution | N23: 0 | O23: *Toggle this to distribute 1/3 of accumulated cash in Year 3 & 4.
L24: LLC/C-corp | N24: C-corp | O24: *To qualify for QSBS, TEV must be <$70M you must be a C-corp and fit certain industry requirements (many except financial and professional services firms, certain categories of healthcare, and certain other excluded businesses).
B25: Total Sources | C25: =H25 | D25: =C25/$N$17 | E25: =C25/$H$25 | G25: Total Uses | H25: =SUM(H16:H18) | I25: =H25/$N$17 | J25: =H25/$H$25 | L25: Seller Equity Rollover | N25: 0.125 | O25: QSBS | Insights | Holland & Knight
L26: Earnout | N26: 0 | O26: *This is meant to be a simple example of an earnout; earnout structures can vary.
L27: Earnout Amount | N27: 0
B28: Summary Financials | L28: Y1 Revenue Threshold | N28: 0
E30: TXN Close | J30: TXN + 5
A31: x | B31: Income Statement | L31: Assumptions & Source Notes
C33: =EDATE(D33,-12) | D33: =EDATE(E33,-12) | E33: =N18 | F33: =EDATE(E33,12) | G33: =EDATE(F33,12) | H33: =EDATE(G33,12) | I33: =EDATE(H33,12) | J33: =EDATE(I33,12) | L33: Melissa 6/17: core $1.5M revenue / $500K EBITDA; 5% organic growth; equity + seller note, no bank debt at close.
B34: Ending ARR | C34: 2684 | D34: 3720 | E34: 4750 | F34: =E34*(1+F35) | G34: =F34*(1+G35) | H34: =G34*(1+H35) | I34: =H34*(1+I35) | J34: =I34*(1+J35) | L34: Seller note base: 30% of TEV proxy, 7% interest. Rollover base: 12.5%. | O34: *Use this if you are looking at an ARR multiple deal. Revenue for a period is calculated as the average of beginning and ending ARR.
B35: Growth | D35: =D34/C34-1 | E35: =E34/D34-1 | F35: 0.22894737 | G35: 0.26713062 | H35: 0.29015632 | I35: 0.30762984 | J35: 0.31181256 | L35: Historical C/D periods are set to 0/TBD because source material did not provide them.
B37: GAAP Revenue | C37: 0 | D37: 0 | E37: 1500 | F37: =IF(N16="ARR",AVERAGE(F34,E34),E37*(1+F38)) | G37: =IF(O16="ARR",AVERAGE(G34,F34),F37*(1+G38)) | H37: =IF(P16="ARR",AVERAGE(H34,G34),G37*(1+H38)) | I37: =IF(Q16="ARR",AVERAGE(I34,H34),H37*(1+I38)) | J37: =IF(R16="ARR",AVERAGE(J34,I34),I37*(1+J38)) | L37: =_xlfn.RRI(2,C37,E37) | O37: *It is difficult to accelerate the growth of a business that is not already consistently growing at a solid pace.
B38: Growth | D38: =D37/C37-1 | E38: =E37/D37-1 | F38: 0.05 | G38: 0.05 | H38: 0.05 | I38: 0.05 | J38: 0.05 | O38: *Forecast revenue here if you are looking at an EBITDA multiple deal. For an ARR deal, you do not need historical revenue numbers.
B40: GAAP EBITDA | C40: 0 | D40: 0 | E40: 500 | F40: =F41*F37 | G40: =G41*G37 | H40: =H41*H37 | I40: =I41*I37 | J40: =J41*J37 | L40: =_xlfn.RRI(2,C40,E40) | O40: *In the short/medium run, margins in ETA often decline and remain lower than historical margins (see research linked below for more). We rarely see a search fund business of scale with margins greater than 35%.
B41: Margin | C41: =C40/C37 | D41: =D40/D37 | E41: =E40/E37 | F41: 0.33333333 | G41: 0.33333333 | H41: 0.33333333 | I41: 0.33333333 | J41: 0.33333333 | O41: Research on EBITDA Margins in ETA - Thomas, Stevens, & Wasserstein
B43: GAAP EBITDA | F43: =F40 | G43: =G40 | H43: =H40 | I43: =I40 | J43: =J40
B44: Depreciation | F44: =-($L$44*F37) | G44: =-($L$44*G37) | H44: =-($L$44*H37) | I44: =-($L$44*I37) | J44: =-($L$44*J37) | L44: 0.01 | M44: % of Revenue | O44: *For asset-light search fund target businesses, depreciation will likely be minimal at around ~1-3% of revenue.
B45: EBIT | F45: =SUM(F43:F44) | G45: =SUM(G43:G44) | H45: =SUM(H43:H44) | I45: =SUM(I43:I44) | J45: =SUM(J43:J44)
B47: Interest | F47: =-F80-F89 | G47: =-G80-G89 | H47: =-H80-H89 | I47: =-I80-I89 | J47: =-J80-J89
B48: EBT | F48: =F45+F47 | G48: =G45+G47 | H48: =H45+H47 | I48: =I45+I47 | J48: =J45+J47
B50: Taxes Owed / Distributed | E50: =IF(N24="LLC",45%,26.5%) | F50: =-$E$50*F48 | G50: =-$E$50*G48 | H50: =-$E$50*H48 | I50: =-$E$50*I48 | J50: =-$E$50*J48
B51: Net Income | F51: =F48+F50 | G51: =G48+G50 | H51: =H48+H50 | I51: =I48+I50 | J51: =J48+J50
...

Sheet Pest Base Case
B2: G&B Pest Multi-Acquisition Model - First Pass
B3: Built from G&B Financial Model Template.xlsx. $000s unless otherwise indicated. Yellow cells are inputs; green cells are formulas.
D6: Close | E6: Y1 | F6: Y2 | G6: Y3 | H6: Y4 | I6: Y5 | M6: Source / status | N6: Notes
B8: Core business assumptions
B9: Revenue | D9: 1500 | M9: Melissa call 2026-06-17 | N9: Core business: $1.5M revenue.
B10: EBITDA | D10: 500 | M10: Melissa call 2026-06-17 | N10: Core business: $500K EBITDA, 33.3% margin.
B11: Labor / COGS % revenue | D11: 0.4 | M11: Melissa call 2026-06-17 | N11: 40% labor / COGS.
B12: Organic growth | D12: 0.05 | M12: Melissa call 2026-06-17 | N12: Melissa recommended ~5% organic growth.
B13: Initial tech count | D13: 6 | M13: Guillermo/Carlos 2026-06-17 | N13: 6-person team; technician count still needs diligence.
B14: Revenue / tech proxy | D14: =D9/D13 | M14: Formula | N14: Useful only after technician count is verified.
B17: Transaction assumptions
B18: Prior offer / TEV proxy | D18: 2500 | M18: Melissa call 2026-06-17 | N18: Seller reportedly had $2.5M offer last year; use as proxy, not valuation conclusion.
B19: Entry multiple proxy | D19: =D18/D10 | M19: Formula | N19: Implied by prior-offer proxy and $500K EBITDA.
B20: Transaction costs | D20: 0.05 | M20: Baseline workbook | N20: Carryover placeholder from single-acquisition model; diligence needed.
B21: Cash to balance sheet | D21: 200 | M21: Baseline workbook | N21: Placeholder from baseline workbook; adjust after operating cash need is known.
B22: Seller note % of TEV | D22: 0.3 | M22: Model input / Melissa structure | N22: Structure lever; stress-tested on Stress Tests tab.
B23: Seller note interest rate | D23: 0.07 | M23: Melissa call 2026-06-17 | N23: Melissa range 6-8%; base at midpoint.
B24: Seller note tenor | D24: 6 | M24: Melissa call 2026-06-17 | N24: Melissa range 5-7 years; base at midpoint.
B25: Rollover equity % | D25: 0.125 | M25: Jay + Melissa 2026-06-17 | N25: Jay suggested 10-15% max; Melissa said minority governance risk is low.
B26: Term debt at close | D26: 0 | M26: Melissa call 2026-06-17 | N26: No bank debt expected at this size.
B27: Bank debt threshold EBITDA | D27: 2000 | M27: Melissa call 2026-06-17 | N27: ~$2M EBITDA minimum for bank debt.
B28: Indicative bank facility | D28: 5000 | M28: Melissa call 2026-06-17 | N28: ~$5M facility once threshold is reached.
B31: Sources & uses
B32: TEV | D32: =D18 | M32: Formula | N32: Capital stack is intentionally simple for the first pass.
B33: Transaction costs | D33: =D18*D20
B34: Cash to balance sheet | D34: =D21
B35: Total uses | D35: =SUM(D32:D34)
B36: Seller note | D36: =D18*D22
B37: Seller rollover | D37: =D18*D25
B38: Term debt | D38: =D26
B39: Investor equity required | D39: =D35-D36-D37-D38
B40: Check | D40: =D35-SUM(D36:D39)
B43: Operating forecast
D44: Close | E44: Y1 | F44: Y2 | G44: Y3 | H44: Y4 | I44: Y5
B45: Core revenue | D45: =D9 | E45: =D45*(1+$D$12) | F45: =E45*(1+$D$12) | G45: =F45*(1+$D$12) | H45: =G45*(1+$D$12) | I45: =H45*(1+$D$12)
B46: Acquired revenue | D46: ='M&A Schedule'!D22 | E46: ='M&A Schedule'!E22 | F46: ='M&A Schedule'!F22 | G46: ='M&A Schedule'!G22 | H46: ='M&A Schedule'!H22 | I46: ='M&A Schedule'!I22
B47: Total revenue | D47: =SUM(D45:D46) | E47: =SUM(E45:E46) | F47: =SUM(F45:F46) | G47: =SUM(G45:G46) | H47: =SUM(H45:H46) | I47: =SUM(I45:I46)
B48: Core EBITDA | D48: =D10 | E48: =D48*(1+$D$12) | F48: =E48*(1+$D$12) | G48: =F48*(1+$D$12) | H48: =G48*(1+$D$12) | I48: =H48*(1+$D$12)
B49: Acquired EBITDA | D49: ='M&A Schedule'!D46 | E49: ='M&A Schedule'!E46 | F49: ='M&A Schedule'!F46 | G49: ='M&A Schedule'!G46 | H49: ='M&A Schedule'!H46 | I49: ='M&A Schedule'!I46
B50: Corporate costs | D50: =SUM(D57:D60) | E50: =SUM(E57:E60) | F50: =SUM(F57:F60) | G50: =SUM(G57:G60) | H50: =SUM(H57:H60) | I50: =SUM(I57:I60)
...

Sheet M&A Schedule
B2: M&A Schedule
B3: Acquisition cohorts use Melissa's first-pass structure. Inputs are deliberately average profiles, not target-level diligence.
D6: Close | E6: Y1 | F6: Y2 | G6: Y3 | H6: Y4 | I6: Y5 | J6: Source / status | K6: Notes
B8: Acquisition count by cohort
B9: Core platform | D9: 1 | E9: 0 | F9: 0 | G9: 0 | H9: 0 | I9: 0 | J9: Melissa / live target | K9: Existing $1.5M revenue, $500K EBITDA business.
B10: Aquihire / small book | D10: 0 | E10: 1 | F10: 2 | G10: 2 | H10: 2 | I10: 2 | J10: Melissa example | K10: $500K revenue, $100K EBITDA, 2 technicians.
B11: Platform tuck-in | D11: 0 | E11: 0 | F11: 0 | G11: 1 | H11: 1 | I11: 1 | J11: TBD | K11: Placeholder count only; profile needs real deal-flow evidence.
B12: De novo crews | D12: 0 | E12: 0 | F12: 0 | G12: 0 | H12: 0 | I12: 0 | J12: Lower priority | K12: Melissa reframed as organic growth; aquihire preferred.
B17: Annual acquired revenue contribution
B18: Core platform | D18: =D9*'Pest Base Case'!$D$9 | E18: =E9*'Pest Base Case'!$D$9 | F18: =F9*'Pest Base Case'!$D$9 | G18: =G9*'Pest Base Case'!$D$9 | H18: =H9*'Pest Base Case'!$D$9 | I18: =I9*'Pest Base Case'!$D$9
B19: Aquihire / small book | D19: =SUM($D10:D10)*$D$29 | E19: =SUM($D10:E10)*$D$29 | F19: =SUM($D10:F10)*$D$29 | G19: =SUM($D10:G10)*$D$29 | H19: =SUM($D10:H10)*$D$29 | I19: =SUM($D10:I10)*$D$29
B20: Platform tuck-in | D20: =SUM($D11:D11)*$D$30 | E20: =SUM($D11:E11)*$D$30 | F20: =SUM($D11:F11)*$D$30 | G20: =SUM($D11:G11)*$D$30 | H20: =SUM($D11:H11)*$D$30 | I20: =SUM($D11:I11)*$D$30
B21: De novo crews | D21: =SUM($D12:D12)*$D$31 | E21: =SUM($D12:E12)*$D$31 | F21: =SUM($D12:F12)*$D$31 | G21: =SUM($D12:G12)*$D$31 | H21: =SUM($D12:H12)*$D$31 | I21: =SUM($D12:I12)*$D$31
B22: Total acquired revenue | D22: =SUM(D19:D21) | E22: =SUM(E19:E21) | F22: =SUM(F19:F21) | G22: =SUM(G19:G21) | H22: =SUM(H19:H21) | I22: =SUM(I19:I21)
B26: Average acquisition profile
B27: Core platform revenue | D27: 1500 | J27: Melissa call
B28: Core platform EBITDA | D28: 500 | J28: Melissa call
B29: Aquihire revenue | D29: 500 | J29: Melissa example
B30: Platform tuck-in revenue | D30: 1500 | J30: TBD / placeholder
B31: De novo crew revenue | D31: 0 | J31: Not modeled
B32: Aquihire EBITDA | D32: 100 | J32: Melissa example
B33: Platform tuck-in EBITDA | D33: 300 | J33: TBD / placeholder
B34: De novo crew EBITDA | D34: 0 | J34: Not modeled
B35: Aquihire techs | D35: 2 | J35: Melissa example
B41: Annual acquired EBITDA contribution
B42: Core platform | D42: =D9*$D$28 | E42: =E9*$D$28 | F42: =F9*$D$28 | G42: =G9*$D$28 | H42: =H9*$D$28 | I42: =I9*$D$28
B43: Aquihire / small book | D43: =SUM($D10:D10)*$D$32 | E43: =SUM($D10:E10)*$D$32 | F43: =SUM($D10:F10)*$D$32 | G43: =SUM($D10:G10)*$D$32 | H43: =SUM($D10:H10)*$D$32 | I43: =SUM($D10:I10)*$D$32
B44: Platform tuck-in | D44: =SUM($D11:D11)*$D$33 | E44: =SUM($D11:E11)*$D$33 | F44: =SUM($D11:F11)*$D$33 | G44: =SUM($D11:G11)*$D$33 | H44: =SUM($D11:H11)*$D$33 | I44: =SUM($D11:I11)*$D$33
B45: De novo crews | D45: =SUM($D12:D12)*$D$34 | E45: =SUM($D12:E12)*$D$34 | F45: =SUM($D12:F12)*$D$34 | G45: =SUM($D12:G12)*$D$34 | H45: =SUM($D12:H12)*$D$34 | I45: =SUM($D12:I12)*$D$34
B46: Total acquired EBITDA | D46: =SUM(D43:D45) | E46: =SUM(E43:E45) | F46: =SUM(F43:F45) | G46: =SUM(G43:G45) | H46: =SUM(H43:H45) | I46: =SUM(I43:I45)
B50: Acquisition cash need
B51: Aquihire TEV multiple | D51: 3 | J51: TBD | K51: Placeholder only. Replace with broker / owner evidence.
B52: Tuck-in TEV multiple | D52: 5 | J52: TBD | K52: Placeholder only. Market notes suggest 7-10x tuck-ins, likely too high for G&B without a wedge.
B53: Annual aquihire TEV | D53: =SUM(D10:I10)*$D$51*$D$32
B54: Annual tuck-in TEV | D54: =SUM(D11:I11)*$D$52*$D$33
B55: Total modeled acquisition TEV | D55: =D53+D54 | K55: Use only as a directional capital need; no acquisition-by-acquisition timing yet.

Sheet Stress Tests
B2: Seller Note / Rollover / Interest-Rate Stress Tests
B3: All tests use the base-case adjusted EBITDA path and change structure levers only.
B6: Scenario | C6: Seller note % | D6: Rate | E6: Tenor | F6: Rollover % | G6: Min DSCR Y1-Y5 | H6: Verdict
B7: Low seller note / low rate | C7: 0.2 | D7: 0.06 | E7: 7 | F7: 0.1 | G7: =MIN('Pest Base Case'!E64/(('Pest Base Case'!$D$18*C7*D7)+('Pest Base Case'!$D$18*C7/E7)),'Pest Base Case'!F64/(('Pest Base Case'!$D$18*C7*D7)+('Pest Base Case'!$D$18*C7/E7)),'Pest Base Case'!G64/(('Pest Base Case'!$D$18*C7*D7)+('Pest Base Case'!$D$18*C7/E7)),'Pest Base Case'!H64/(('Pest Base Case'!$D$18*C7*D7)+('Pest Base Case'!$D$18*C7/E7)),'Pest Base Case'!I64/(('Pest Base Case'!$D$18*C7*D7)+('Pest Base Case'!$D$18*C7/E7))) | H7: =IF(G7<1,"Breaks cash flow",IF(G7<1.25,"Marginal cushion","Supported in first pass"))
B8: Base case | C8: 0.3 | D8: 0.07 | E8: 6 | F8: 0.125 | G8: =MIN('Pest Base Case'!E64/(('Pest Base Case'!$D$18*C8*D8)+('Pest Base Case'!$D$18*C8/E8)),'Pest Base Case'!F64/(('Pest Base Case'!$D$18*C8*D8)+('Pest Base Case'!$D$18*C8/E8)),'Pest Base Case'!G64/(('Pest Base Case'!$D$18*C8*D8)+('Pest Base Case'!$D$18*C8/E8)),'Pest Base Case'!H64/(('Pest Base Case'!$D$18*C8*D8)+('Pest Base Case'!$D$18*C8/E8)),'Pest Base Case'!I64/(('Pest Base Case'!$D$18*C8*D8)+('Pest Base Case'!$D$18*C8/E8))) | H8: =IF(G8<1,"Breaks cash flow",IF(G8<1.25,"Marginal cushion","Supported in first pass"))
B9: High seller note / high rate | C9: 0.4 | D9: 0.08 | E9: 5 | F9: 0.15 | G9: =MIN('Pest Base Case'!E64/(('Pest Base Case'!$D$18*C9*D9)+('Pest Base Case'!$D$18*C9/E9)),'Pest Base Case'!F64/(('Pest Base Case'!$D$18*C9*D9)+('Pest Base Case'!$D$18*C9/E9)),'Pest Base Case'!G64/(('Pest Base Case'!$D$18*C9*D9)+('Pest Base Case'!$D$18*C9/E9)),'Pest Base Case'!H64/(('Pest Base Case'!$D$18*C9*D9)+('Pest Base Case'!$D$18*C9/E9)),'Pest Base Case'!I64/(('Pest Base Case'!$D$18*C9*D9)+('Pest Base Case'!$D$18*C9/E9))) | H9: =IF(G9<1,"Breaks cash flow",IF(G9<1.25,"Marginal cushion","Supported in first pass"))
B10: No rollover / more cash need | C10: 0.3 | D10: 0.07 | E10: 6 | F10: 0 | G10: =MIN('Pest Base Case'!E64/(('Pest Base Case'!$D$18*C10*D10)+('Pest Base Case'!$D$18*C10/E10)),'Pest Base Case'!F64/(('Pest Base Case'!$D$18*C10*D10)+('Pest Base Case'!$D$18*C10/E10)),'Pest Base Case'!G64/(('Pest Base Case'!$D$18*C10*D10)+('Pest Base Case'!$D$18*C10/E10)),'Pest Base Case'!H64/(('Pest Base Case'!$D$18*C10*D10)+('Pest Base Case'!$D$18*C10/E10)),'Pest Base Case'!I64/(('Pest Base Case'!$D$18*C10*D10)+('Pest Base Case'!$D$18*C10/E10))) | H10: =IF(G10<1,"Breaks cash flow",IF(G10<1.25,"Marginal cushion","Supported in first pass"))
B11: Max rollover / max seller carry | C11: 0.4 | D11: 0.08 | E11: 7 | F11: 0.15 | G11: =MIN('Pest Base Case'!E64/(('Pest Base Case'!$D$18*C11*D11)+('Pest Base Case'!$D$18*C11/E11)),'Pest Base Case'!F64/(('Pest Base Case'!$D$18*C11*D11)+('Pest Base Case'!$D$18*C11/E11)),'Pest Base Case'!G64/(('Pest Base Case'!$D$18*C11*D11)+('Pest Base Case'!$D$18*C11/E11)),'Pest Base Case'!H64/(('Pest Base Case'!$D$18*C11*D11)+('Pest Base Case'!$D$18*C11/E11)),'Pest Base Case'!I64/(('Pest Base Case'!$D$18*C11*D11)+('Pest Base Case'!$D$18*C11/E11))) | H11: =IF(G11<1,"Breaks cash flow",IF(G11<1.25,"Marginal cushion","Supported in first pass"))
B12: Interest shock | C12: 0.3 | D12: 0.09 | E12: 6 | F12: 0.125 | G12: =MIN('Pest Base Case'!E64/(('Pest Base Case'!$D$18*C12*D12)+('Pest Base Case'!$D$18*C12/E12)),'Pest Base Case'!F64/(('Pest Base Case'!$D$18*C12*D12)+('Pest Base Case'!$D$18*C12/E12)),'Pest Base Case'!G64/(('Pest Base Case'!$D$18*C12*D12)+('Pest Base Case'!$D$18*C12/E12)),'Pest Base Case'!H64/(('Pest Base Case'!$D$18*C12*D12)+('Pest Base Case'!$D$18*C12/E12)),'Pest Base Case'!I64/(('Pest Base Case'!$D$18*C12*D12)+('Pest Base Case'!$D$18*C12/E12))) | H12: =IF(G12<1,"Breaks cash flow",IF(G12<1.25,"Marginal cushion","Supported in first pass"))
B16: Cash-flow sensitivity
B18: EBITDA haircut | C18: Min DSCR base structure | D18: Cash after debt Y1 | E18: Cash after debt Y5 | F18: Verdict
B19: 0 | C19: =MIN(('Pest Base Case'!E64*(1-B19))/(('Pest Base Case'!$D$36*'Pest Base Case'!$D$23)+('Pest Base Case'!$D$36/'Pest Base Case'!$D$24)),('Pest Base Case'!F64*(1-B19))/(('Pest Base Case'!$D$36*'Pest Base Case'!$D$23)+('Pest Base Case'!$D$36/'Pest Base Case'!$D$24)),('Pest Base Case'!G64*(1-B19))/(('Pest Base Case'!$D$36*'Pest Base Case'!$D$23)+('Pest Base Case'!$D$36/'Pest Base Case'!$D$24)),('Pest Base Case'!H64*(1-B19))/(('Pest Base Case'!$D$36*'Pest Base Case'!$D$23)+('Pest Base Case'!$D$36/'Pest Base Case'!$D$24)),('Pest Base Case'!I64*(1-B19))/(('Pest Base Case'!$D$36*'Pest Base Case'!$D$23)+('Pest Base Case'!$D$36/'Pest Base Case'!$D$24))) | D19: ='Pest Base Case'!E70*(1-B19) | E19: ='Pest Base Case'!I70*(1-B19) | F19: =IF(C19<1,"Breaks",IF(C19<1.25,"Tight","OK"))
B20: 0.1 | C20: =MIN(('Pest Base Case'!E64*(1-B20))/(('Pest Base Case'!$D$36*'Pest Base Case'!$D$23)+('Pest Base Case'!$D$36/'Pest Base Case'!$D$24)),('Pest Base Case'!F64*(1-B20))/(('Pest Base Case'!$D$36*'Pest Base Case'!$D$23)+('Pest Base Case'!$D$36/'Pest Base Case'!$D$24)),('Pest Base Case'!G64*(1-B20))/(('Pest Base Case'!$D$36*'Pest Base Case'!$D$23)+('Pest Base Case'!$D$36/'Pest Base Case'!$D$24)),('Pest Base Case'!H64*(1-B20))/(('Pest Base Case'!$D$36*'Pest Base Case'!$D$23)+('Pest Base Case'!$D$36/'Pest Base Case'!$D$24)),('Pest Base Case'!I64*(1-B20))/(('Pest Base Case'!$D$36*'Pest Base Case'!$D$23)+('Pest Base Case'!$D$36/'Pest Base Case'!$D$24))) | D20: ='Pest Base Case'!E70*(1-B20) | E20: ='Pest Base Case'!I70*(1-B20) | F20: =IF(C20<1,"Breaks",IF(C20<1.25,"Tight","OK"))
B21: 0.2 | C21: =MIN(('Pest Base Case'!E64*(1-B21))/(('Pest Base Case'!$D$36*'Pest Base Case'!$D$23)+('Pest Base Case'!$D$36/'Pest Base Case'!$D$24)),('Pest Base Case'!F64*(1-B21))/(('Pest Base Case'!$D$36*'Pest Base Case'!$D$23)+('Pest Base Case'!$D$36/'Pest Base Case'!$D$24)),('Pest Base Case'!G64*(1-B21))/(('Pest Base Case'!$D$36*'Pest Base Case'!$D$23)+('Pest Base Case'!$D$36/'Pest Base Case'!$D$24)),('Pest Base Case'!H64*(1-B21))/(('Pest Base Case'!$D$36*'Pest Base Case'!$D$23)+('Pest Base Case'!$D$36/'Pest Base Case'!$D$24)),('Pest Base Case'!I64*(1-B21))/(('Pest Base Case'!$D$36*'Pest Base Case'!$D$23)+('Pest Base Case'!$D$36/'Pest Base Case'!$D$24))) | D21: ='Pest Base Case'!E70*(1-B21) | E21: ='Pest Base Case'!I70*(1-B21) | F21: =IF(C21<1,"Breaks",IF(C21<1.25,"Tight","OK"))
B22: 0.3 | C22: =MIN(('Pest Base Case'!E64*(1-B22))/(('Pest Base Case'!$D$36*'Pest Base Case'!$D$23)+('Pest Base Case'!$D$36/'Pest Base Case'!$D$24)),('Pest Base Case'!F64*(1-B22))/(('Pest Base Case'!$D$36*'Pest Base Case'!$D$23)+('Pest Base Case'!$D$36/'Pest Base Case'!$D$24)),('Pest Base Case'!G64*(1-B22))/(('Pest Base Case'!$D$36*'Pest Base Case'!$D$23)+('Pest Base Case'!$D$36/'Pest Base Case'!$D$24)),('Pest Base Case'!H64*(1-B22))/(('Pest Base Case'!$D$36*'Pest Base Case'!$D$23)+('Pest Base Case'!$D$36/'Pest Base Case'!$D$24)),('Pest Base Case'!I64*(1-B22))/(('Pest Base Case'!$D$36*'Pest Base Case'!$D$23)+('Pest Base Case'!$D$36/'Pest Base Case'!$D$24))) | D22: ='Pest Base Case'!E70*(1-B22) | E22: ='Pest Base Case'!I70*(1-B22) | F22: =IF(C22<1,"Breaks",IF(C22<1.25,"Tight","OK"))

Sheet Investor Questions
B2: Investor-Facing Question Set: Jeff / Anacapa
B5: Topic | C5: Question | D5: Why it matters | E5: Owner / next use
B6: Cap table | C6: If the first pest platform is only ~$500K EBITDA, what cap-table shape would Anacapa support: same committed investor base, smaller first-close syndicate, or reserved follow-on capital? | D6: Melissa says committed capital should bridge the first close to the flywheel; Kay needs investor appetite before overbuilding the strategy. | E6: Jeff / Anacapa
B7: Seller note | C7: At what seller-note quantum does Anacapa become uncomfortable for a small, owner-operated pest platform? | D7: Seller note is the primary lever to make the seller's proceeds work without overloading cash flow. | E7: Jeff / Anacapa
B8: Rollover | C8: Is 10-15% seller rollover acceptable in a search-style cap table if the seller has no governance control? | D8: Jay suggested 10-15% max; Melissa sees low governance risk, but investor support matters. | E8: Jeff / Anacapa
B9: Interest rate | C9: Would Anacapa underwrite a 6-8% seller note today, and what cushion would they require if rates move up? | D9: Debt-service pressure is the gating issue for a small platform. | E9: Jeff / Anacapa
B10: Bank debt | C10: Does the ~$2M EBITDA / ~$5M facility threshold match Anacapa's current lender read for pest services? | D10: Model assumes no bank debt at close and future debt only after scale. | E10: Jeff / Anacapa
B11: Buy-box fit | C11: Is an undersized but high-margin $500K EBITDA pest platform acceptable if the multi-acquisition path is credible? | D11: CIO issue: initial asset is below preferred scale, but could be a wedge into a dense market. | E11: Jeff / Anacapa
B12: Wedge | C12: Does the luxury retail / hospitality discretion wedge make pest more underwritable, or is it too narrow for an investor-backed strategy? | D12: Jay's warning: broad pest is too competitive; specialty is the opening. | E12: Jeff / Anacapa
B13: Diligence | C13: What proof would make the acquisition path real: client count, route density, revenue per technician, retention, pricing uplift, or signed seller interest? | D13: Avoids modeling sophistication without diligence-grade inputs. | E13: Jeff / Anacapa

Sheet Source Notes
B2: Source Notes / Assumption Register
B5: Source | C5: Model use | D5: Fact / guidance used | E5: Status
B6: Melissa Rosenblatt call 2026-06-17 | C6: Core model architecture | D6: Core business: $1.5M revenue, $500K EBITDA, 40% labor/COGS, no office manager, answering service. Build core IS, corporate cost section, M&A schedule, combined IS. | E6: Used
B7: Melissa analysis Google Doc 2026-06-17 | C7: Operating frame | D7: Full analysis reinforced aquihire over de novo, holdco vs branded roll-up as open, and the need for one visible model plus a decision memo. | E7: Used
B8: Melissa transcript Google Doc 2026-06-17 | C8: Transcript check | D8: gog docs cat returned only: Granola transcript unavailable in response. No transcript-only facts were used. | E8: Blocked / explicit limitation
B9: Melissa Rosenblatt call 2026-06-17 | C9: Capital structure | D9: First acquisition likely equity + seller note; no bank debt at this size. Bank debt threshold ~$2M EBITDA, facility ~$5M. Seller note 5-7 years, 6-8% interest. | E9: Used
B10: Melissa Rosenblatt / Jay Davis 2026-06-17 | C10: Rollover | D10: Jay suggested 10-15% max; Melissa confirmed minority stake carries no real governance risk. | E10: Used
B11: Guillermo Lavergne brainstorm 2026-06-17 | C11: Target diligence | D11: NJ/NYC commercial pest company: ~$1.5M revenue, ~$500K EBITDA, 6-person team, 98% retention, Cartier/Chelsea Market/Google proof points. | E11: Used
B12: Carlos check-in 2026-06-17 | C12: Thesis support | D12: Carlos validated small NJ operator / NYC thesis; holding-company structure remains live. | E12: Used
B13: WSN pest calibration 2026-06-17 | C13: Diligence gate | D13: Cash-flow quality and owner draw need verification before more time is spent. | E13: Used as missing-input flag
B14: Jay Davis 2026-06-09 | C14: Market structure | D14: Broad pest is crowded/liquid; specialty/premium wedge is the opening if growth is real. | E14: Used
B15: Premium Pest Scorecard Apr 2026 | C15: Industry context | D15: 19,000+ firms, strong fragmentation, 25-35% EBITDA margins for well-run operators, asset-light service model. | E15: Used as context, not hardcoded forecast
B16: Niche intelligence 2026-05-26 | C16: Market multiple context | D16: PE consolidation deepening; 10-15x platform / 7-10x tuck-in market notes. | E16: Flagged: not used as base valuation because it may not fit G&B's small target
... B18: G&B Financial Model Template.xlsx | C18: Baseline structure | D18: Master template from Manager Documents / G&B Master Templates. Sources/uses, cash flow, debt schedule, returns framework retained and used as the reference single-acquisition structure. | E18: Used as baseline

Sheet Model Template
A2: x | B2: G&B Financial Model Template - Baseline Reference
B4: Instructions
B5: 1. Fill out historical Revenue and EBITDA. Project Revenue and EBITDA for the 5 year period.
B6: 2. Fill out the transaction assumptions with TEV & leverage and other key structure information.
B7: 3. Adjust the remaining assumptions in the yellow boxes for the cash flow statement and debt schedule as appropriate.
B8: 4. Check the "check" to make sure your business has the cash flow profile to support your capital structure.
B9: 5. Modify the deal structure and exit assumptions if needed. Note: If the model is getting errors, turn the circuit breaker to 0 and back to 1.
B10: 6. Evaluate the returns.
B12: $000s unless otherwise indicated | L12: Check | N12: =IF(SUM(F67:J67)>0,"Cash Shortfall","OK") | O12: *Check here to make sure your business has enough cash flow to support the capital structure.
A14: x | B14: Sources | G14: Uses | L14: Transaction Assumptions
C15: Amount | D15: =CONCATENATE("x",$N$16) | E15: % of Total | H15: Amount | I15: =CONCATENATE("x",$N$16) | J15: % of Total | L15: TEV | N15: 8500 | O15: *Refer to the Search Fund Study to understand median multiples, revenue, EBITDA, and more.
B16: Term Debt | C16: =D16*N17 | D16: =N20 | E16: =C16/C25 | G16: TEV | H16: =N15 | I16: =H16/$N$17 | J16: =H16/$H$25 | L16: Entry Multiple | N16: EBITDA
B17: Seller Debt | C17: =N21 | D17: =C17/$N$17 | E17: =C17/C25 | G17: Fees | H17: =H16*N19 | I17: =H17/$N$17 | J17: =H17/$H$25 | L17: =IF(N16="ARR","Ending ARR","LTM EBITDA") | N17: =IF(N16="ARR",E34,E40)
B18: Total Debt | C18: =SUM(C16:C17) | D18: =C18/$N$17 | E18: =C18/$C$25 | G18: Cash to B/S | H18: =N22 | I18: =H18/$N$17 | J18: =H18/$H$25 | L18: LTM Period | N18: 46022 | O18: 2024 Search Fund Study | Stanford Graduate School of Business
L19: Transaction Costs | N19: 0.05
B20: Equity | D20: % of Equity | L20: =CONCATENATE("Term Debt x",N16) | N20: 2.5
B21: Seller Equity Rollover | C21: =D21*C23 | D21: =N25 | E21: =C21/C25 | L21: Seller Debt Quantum | N21: 1000
B22: Investor Equity | C22: =D22*C23 | D22: =1-D21 | E22: =C22/C25 | L22: Cash to B/S | N22: 200 | O22: *Typically, searcher(s) put de minimis cash on the balance sheet.
B23: Total Equity | C23: =C25-C18 | D23: =SUM(C21:C22)/C23 | E23: =C23/C25 | L23: ECF Distribution | N23: 0 | O23: *Toggle this to distribute 1/3 of accumulated cash in Year 3 & 4.
L24: LLC/C-corp | N24: C-corp | O24: *To qualify for QSBS, TEV must be <$70M you must be a C-corp and fit certain industry requirements (many except financial and professional services firms, certain categories of healthcare, and certain other excluded businesses).
B25: Total Sources | C25: =H25 | D25: =C25/$N$17 | E25: =C25/$H$25 | G25: Total Uses | H25: =SUM(H16:H18) | I25: =H25/$N$17 | J25: =H25/$H$25 | L25: Seller Equity Rollover | N25: 0.1 | O25: QSBS | Insights | Holland & Knight
L26: Earnout | N26: 0 | O26: *This is meant to be a simple example of an earnout; earnout structures can vary.
L27: Earnout Amount | N27: 500
B28: Summary Financials | L28: Y1 Revenue Threshold | N28: 5000
E30: TXN Close | J30: TXN + 5
A31: x | B31: Income Statement | L31: Assumptions & BK Growth Notes
C33: =EDATE(D33,-12) | D33: =EDATE(E33,-12) | E33: =N18 | F33: =EDATE(E33,12) | G33: =EDATE(F33,12) | H33: =EDATE(G33,12) | I33: =EDATE(H33,12) | J33: =EDATE(I33,12) | L33: CAGR
B34: Ending ARR | C34: 2684 | D34: 3720 | E34: 4750 | F34: =E34*(1+F35) | G34: =F34*(1+G35) | H34: =G34*(1+H35) | I34: =H34*(1+I35) | J34: =I34*(1+J35) | L34: =_xlfn.RRI(2,C34,E34) | O34: *Use this if you are looking at an ARR multiple deal. Revenue for a period is calculated as the average of beginning and ending ARR.
B35: Growth | D35: =D34/C34-1 | E35: =E34/D34-1 | F35: 0.22894737 | G35: 0.26713062 | H35: 0.29015632 | I35: 0.30762984 | J35: 0.31181256
B37: GAAP Revenue | C37: 2123 | D37: 3202 | E37: 4235 | F37: =IF(N16="ARR",AVERAGE(F34,E34),E37*(1+F38)) | G37: =IF(O16="ARR",AVERAGE(G34,F34),F37*(1+G38)) | H37: =IF(P16="ARR",AVERAGE(H34,G34),G37*(1+H38)) | I37: =IF(Q16="ARR",AVERAGE(I34,H34),H37*(1+I38)) | J37: =IF(R16="ARR",AVERAGE(J34,I34),I37*(1+J38)) | L37: =_xlfn.RRI(2,C37,E37) | O37: *It is difficult to accelerate the growth of a business that is not already consistently growing at a solid pace.
B38: Growth | D38: =D37/C37-1 | E38: =E37/D37-1 | F38: 0.25 | G38: 0.25 | H38: 0.28 | I38: 0.3 | J38: 0.31 | O38: *Forecast revenue here if you are looking at an EBITDA multiple deal. For an ARR deal, you do not need historical revenue numbers.
B40: GAAP EBITDA | C40: 465 | D40: 689 | E40: 1256 | F40: =F41*F37 | G40: =G41*G37 | H40: =H41*H37 | I40: =I41*I37 | J40: =J41*J37 | L40: =_xlfn.RRI(2,C40,E40) | O40: *In the short/medium run, margins in ETA often decline and remain lower than historical margins (see research linked below for more). We rarely see a search fund business of scale with margins greater than 35%.
B41: Margin | C41: =C40/C37 | D41: =D40/D37 | E41: =E40/E37 | F41: 0.22 | G41: 0.22 | H41: 0.25 | I41: 0.28 | J41: 0.29 | O41: Research on EBITDA Margins in ETA - Thomas, Stevens, & Wasserstein
B43: GAAP EBITDA | F43: =F40 | G43: =G40 | H43: =H40 | I43: =I40 | J43: =J40
B44: Depreciation | F44: =-($L$44*F37) | G44: =-($L$44*G37) | H44: =-($L$44*H37) | I44: =-($L$44*I37) | J44: =-($L$44*J37) | L44: 0.01 | M44: % of Revenue | O44: *For asset-light search fund target businesses, depreciation will likely be minimal at around ~1-3% of revenue.
B45: EBIT | F45: =SUM(F43:F44) | G45: =SUM(G43:G44) | H45: =SUM(H43:H44) | I45: =SUM(I43:I44) | J45: =SUM(J43:J44)
B47: Interest | F47: =-F80-F89 | G47: =-G80-G89 | H47: =-H80-H89 | I47: =-I80-I89 | J47: =-J80-J89
B48: EBT | F48: =F45+F47 | G48: =G45+G47 | H48: =H45+H47 | I48: =I45+I47 | J48: =J45+J47
B50: Taxes Owed / Distributed | E50: =IF(N24="LLC",45%,26.5%) | F50: =-$E$50*F48 | G50: =-$E$50*G48 | H50: =-$E$50*H48 | I50: =-$E$50*I48 | J50: =-$E$50*J48
B51: Net Income | F51: =F48+F50 | G51: =G48+G50 | H51: =H48+H50 | I51: =I48+I50 | J51: =J48+J50
...

Sheet Growth
A2: x | B2: G&B Model Template
B4: Instructions
B5: 1. Fill out historical Revenue and EBITDA. Project Revenue and EBITDA for the 5 year period.
B6: 2. Fill out the transaction assumptions with TEV & leverage and other key structure information.
B7: 3. Adjust the remaining assumptions in the yellow boxes for the cash flow statement and debt schedule as appropriate.
B8: 4. Check the "check" to make sure your business has the cash flow profile to support your capital structure.
B9: 5. Modify the deal structure and exit assumptions if needed. Note: If the model is getting errors, turn the circuit breaker to 0 and back to 1.
B10: 6. Evaluate the returns.
B12: $000s unless otherwise indicated | L12: Check | N12: =IF(SUM(F67:J67)>0,"Cash Shortfall","OK") | O12: *Check here to make sure your business has enough cash flow to support the capital structure.
A14: x | B14: Sources | G14: Uses | L14: Transaction Assumptions
C15: Amount | D15: =CONCATENATE("x",$N$16) | E15: % of Total | H15: Amount | I15: =CONCATENATE("x",$N$16) | J15: % of Total | L15: TEV | N15: 15000 | O15: *Refer to the Search Fund Study to understand median multiples, revenue, EBITDA, and more.
B16: Term Debt | C16: =D16*N17 | D16: =N20 | E16: =C16/C25 | G16: TEV | H16: =N15 | I16: =H16/$N$17 | J16: =H16/$H$25 | L16: Entry Multiple | N16: ARR
B17: Seller Debt | C17: =N21 | D17: =C17/$N$17 | E17: =C17/C25 | G17: Fees | H17: =H16*N19 | I17: =H17/$N$17 | J17: =H17/$H$25 | L17: =IF(N16="ARR","Ending ARR","LTM EBITDA") | N17: =IF(N16="ARR",E34,E40)
B18: Total Debt | C18: =SUM(C16:C17) | D18: =C18/$N$17 | E18: =C18/$C$25 | G18: Cash to B/S | H18: =N22 | I18: =H18/$N$17 | J18: =H18/$H$25 | L18: LTM Period | N18: 46022 | O18: 2024 Search Fund Study | Stanford Graduate School of Business
L19: Transaction Costs | N19: 0.05
B20: Equity | D20: % of Equity | L20: =CONCATENATE("Term Debt x",N16) | N20: 0.5
B21: Seller Equity Rollover | C21: =D21*C23 | D21: =N25 | E21: =C21/C25 | L21: Seller Debt Quantum | N21: 1000
B22: Investor Equity | C22: =D22*C23 | D22: =1-D21 | E22: =C22/C25 | L22: Cash to B/S | N22: 350 | O22: *Typically, searcher(s) put de minimis cash on the balance sheet.
B23: Total Equity | C23: =C25-C18 | D23: =SUM(C21:C22)/C23 | E23: =C23/C25 | L23: ECF Distribution | N23: 0 | O23: *Toggle this to distribute 1/3 of accumulated cash in Year 3 & 4.
L24: LLC/C-corp | N24: C-corp | O24: *To qualify for QSBS, TEV must be <$70M you must be a C-corp and fit certain industry requirements (many except financial and professional services firms, certain categories of healthcare, and certain other excluded businesses).
B25: Total Sources | C25: =H25 | D25: =C25/$N$17 | E25: =C25/$H$25 | G25: Total Uses | H25: =SUM(H16:H18) | I25: =H25/$N$17 | J25: =H25/$H$25 | L25: Seller Equity Rollover | N25: 0.1 | O25: QSBS | Insights | Holland & Knight
L26: Earnout | N26: 0 | O26: *This is meant to be a simple example of an earnout; earnout structures can vary.
L27: Earnout Amount | N27: 500
B28: Summary Financials | L28: Y1 Revenue Threshold | N28: 5000
E30: TXN Close | J30: TXN + 5
A31: x | B31: Income Statement | L31: Assumptions & BK Growth Notes
C33: =EDATE(D33,-12) | D33: =EDATE(E33,-12) | E33: =N18 | F33: =EDATE(E33,12) | G33: =EDATE(F33,12) | H33: =EDATE(G33,12) | I33: =EDATE(H33,12) | J33: =EDATE(I33,12) | L33: CAGR
B34: Ending ARR | C34: 2138 | D34: 3392 | E34: 5078 | F34: =E34*(1+F35) | G34: =F34*(1+G35) | H34: =G34*(1+H35) | I34: =H34*(1+I35) | J34: =I34*(1+J35) | L34: =_xlfn.RRI(2,C34,E34) | O34: *Use this if you are looking at an ARR multiple deal. Revenue for a period is calculated as the average of beginning and ending ARR.
B35: Growth | D35: =D34/C34-1 | E35: =E34/D34-1 | F35: 0.4185703 | G35: 0.38690914 | H35: 0.354 | I35: 0.33955411 | J35: 0.28793735
B37: GAAP Revenue | C37: 1657 | D37: 2765 | E37: 4235 | F37: =IF(N16="ARR",AVERAGE(F34,E34),E37*(1+F38)) | G37: =IF(O16="ARR",AVERAGE(G34,F34),F37*(1+G38)) | H37: =IF(P16="ARR",AVERAGE(H34,G34),G37*(1+H38)) | I37: =IF(Q16="ARR",AVERAGE(I34,H34),H37*(1+I38)) | J37: =IF(R16="ARR",AVERAGE(J34,I34),I37*(1+J38)) | L37: =_xlfn.RRI(2,C37,E37) | O37: *It is difficult to accelerate the growth of a business that is not already consistently growing at a solid pace.
B38: Growth | D38: =D37/C37-1 | E38: =E37/D37-1 | F38: 0.45 | G38: 0.4 | H38: 0.36 | I38: 0.34 | J38: 0.31 | O38: *Forecast revenue here if you are looking at an EBITDA multiple deal. For an ARR deal, you do not need historical revenue numbers.
B40: GAAP EBITDA | C40: -34 | D40: 105 | E40: 405 | F40: =F41*F37 | G40: =G41*G37 | H40: =H41*H37 | I40: =I41*I37 | J40: =J41*J37 | L40: =IFERROR(_xlfn.RRI(2,C40,E40),"N/A") | O40: *In the short/medium run, margins in ETA often decline and remain lower than historical margins (see research linked below for more). We rarely see a search fund business of scale with margins greater than 35%.
B41: Margin | C41: =C40/C37 | D41: =D40/D37 | E41: =E40/E37 | F41: 0.03 | G41: 0.05 | H41: 0.114 | I41: 0.12 | J41: 0.14 | O41: Research on EBITDA Margins in ETA - Thomas, Stevens, & Wasserstein
B43: GAAP EBITDA | F43: =F40 | G43: =G40 | H43: =H40 | I43: =I40 | J43: =J40
B44: Depreciation | F44: =-($L$44*F37) | G44: =-($L$44*G37) | H44: =-($L$44*H37) | I44: =-($L$44*I37) | J44: =-($L$44*J37) | L44: 0.01 | M44: % of Revenue | O44: *For asset-light search fund target businesses, depreciation will likely be minimal at around ~1-3% of revenue.
B45: EBIT | F45: =SUM(F43:F44) | G45: =SUM(G43:G44) | H45: =SUM(H43:H44) | I45: =SUM(I43:I44) | J45: =SUM(J43:J44)
B47: Interest | F47: =-F80-F89 | G47: =-G80-G89 | H47: =-H80-H89 | I47: =-I80-I89 | J47: =-J80-J89
B48: EBT | F48: =F45+F47 | G48: =G45+G47 | H48: =H45+H47 | I48: =I45+I47 | J48: =J45+J47
B50: Taxes Owed / Distributed | E50: =IF(N24="LLC",45%,26.5%) | F50: =-$E$50*F48 | G50: =-$E$50*G48 | H50: =-$E$50*H48 | I50: =-$E$50*I48 | J50: =-$E$50*J48
B51: Net Income | F51: =F48+F50 | G51: =G48+G50 | H51: =H48+H50 | I51: =I48+I50 | J51: =J48+J50
...

Sheet Value
A2: x | B2: G&B Model Template
B4: Instructions
B5: 1. Fill out historical Revenue and EBITDA. Project Revenue and EBITDA for the 5 year period.
B6: 2. Fill out the transaction assumptions with TEV & leverage and other key structure information.
B7: 3. Adjust the remaining assumptions in the yellow boxes for the cash flow statement and debt schedule as appropriate.
B8: 4. Check the "check" to make sure your business has the cash flow profile to support your capital structure.
B9: 5. Modify the deal structure and exit assumptions if needed. Note: If the model is getting errors, turn the circuit breaker to 0 and back to 1.
B10: 6. Evaluate the returns.
B12: $000s unless otherwise indicated | L12: Check | N12: =IF(SUM(F67:J67)>0,"Cash Shortfall","OK") | O12: *Check here to make sure your business has enough cash flow to support the capital structure.
A14: x | B14: Sources | G14: Uses | L14: Transaction Assumptions
C15: Amount | D15: =CONCATENATE("x",$N$16) | E15: % of Total | H15: Amount | I15: =CONCATENATE("x",$N$16) | J15: % of Total | L15: TEV | N15: =E40*8 | O15: *Refer to the Search Fund Study to understand median multiples, revenue, EBITDA, and more.
B16: Term Debt | C16: =D16*E40 | D16: =N20 | E16: =C16/C25 | G16: TEV | H16: =N15 | I16: =H16/$N$17 | J16: =H16/$H$25 | L16: Entry Multiple | N16: EBITDA
B17: Seller Debt | C17: =N21 | D17: =C17/$N$17 | E17: =C17/C25 | G17: Fees | H17: =H16*N19 | I17: =H17/$N$17 | J17: =H17/$H$25 | L17: =IF(N16="ARR","Ending ARR","LTM EBITDA") | N17: =IF(N16="ARR",E34,E40)
B18: Total Debt | C18: =SUM(C16:C17) | D18: =C18/$N$17 | E18: =C18/$C$25 | G18: Cash to B/S | H18: =N22 | I18: =H18/$N$17 | J18: =H18/$H$25 | L18: LTM Period | N18: 46022 | O18: 2024 Search Fund Study | Stanford Graduate School of Business
L19: Transaction Costs | N19: 0.05
B20: Equity | D20: % of Equity | L20: =CONCATENATE("Term Debt x",N16) | N20: 3
B21: Seller Equity Rollover | C21: =D21*C23 | D21: =N25 | E21: =C21/C25 | L21: Seller Debt Quantum | N21: 1500
B22: Investor Equity | C22: =D22*C23 | D22: =1-D21 | E22: =C22/C25 | L22: Cash to B/S | N22: 200 | O22: *Typically, searcher(s) put de minimis cash on the balance sheet.
B23: Total Equity | C23: =C25-C18 | D23: =SUM(C21:C22)/C23 | E23: =C23/C25 | L23: ECF Distribution | N23: 0 | O23: *Toggle this to distribute 1/3 of accumulated cash in Year 3 & 4.
L24: LLC/C-corp | N24: C-corp | O24: *To qualify for QSBS, TEV must be <$70M you must be a C-corp and fit certain industry requirements (many except financial and professional services firms, certain categories of healthcare, and certain other excluded businesses).
B25: Total Sources | C25: =H25 | D25: =C25/$N$17 | E25: =C25/$H$25 | G25: Total Uses | H25: =SUM(H16:H18) | I25: =H25/$N$17 | J25: =H25/$H$25 | L25: Seller Equity Rollover | N25: 0.1 | O25: QSBS | Insights | Holland & Knight
L26: Earnout | N26: 0 | O26: *This is meant to be a simple example of an earnout; earnout structures can vary.
L27: Earnout Amount | N27: 500
B28: Summary Financials | L28: Y1 Revenue Threshold | N28: 6000
E30: TXN Close | J30: TXN + 5
A31: x | B31: Income Statement | L31: Assumptions & BK Growth Notes
C33: =EDATE(D33,-12) | D33: =EDATE(E33,-12) | E33: =N18 | F33: =EDATE(E33,12) | G33: =EDATE(F33,12) | H33: =EDATE(G33,12) | I33: =EDATE(H33,12) | J33: =EDATE(I33,12) | L33: CAGR
B34: Ending ARR | C34: 9796 | D34: 11304 | E34: 12700 | F34: =E34*(1+F35) | G34: =F34*(1+G35) | H34: =G34*(1+H35) | I34: =H34*(1+I35) | J34: =I34*(1+J35) | L34: =_xlfn.RRI(2,C34,E34) | O34: *Use this if you are looking at an ARR multiple deal. Revenue for a period is calculated as the average of beginning and ending ARR.
B35: Growth | D35: =D34/C34-1 | E35: =E34/D34-1 | F35: 0.060185827 | G35: 0.17641857 | H35: 0.10904284 | I35: 0.20594697 | J35: 0.12189968
B37: GAAP Revenue | C37: 8000 | D37: 9000 | E37: 10000 | F37: =IF(N16="ARR",AVERAGE(F34,E34),E37*(1+F38)) | G37: =IF(O16="ARR",AVERAGE(G34,F34),F37*(1+G38)) | H37: =IF(P16="ARR",AVERAGE(H34,G34),G37*(1+H38)) | I37: =IF(Q16="ARR",AVERAGE(I34,H34),H37*(1+I38)) | J37: =IF(R16="ARR",AVERAGE(J34,I34),I37*(1+J38)) | L37: =_xlfn.RRI(2,C37,E37) | O37: *It is difficult to accelerate the growth of a business that is not already consistently growing at a solid pace.
B38: Growth | D38: =D37/C37-1 | E38: =E37/D37-1 | F38: 0.05 | G38: 0.2 | H38: 0.2 | I38: 0.2 | J38: 0.2 | O38: *Forecast revenue here if you are looking at an EBITDA multiple deal. For an ARR deal, you do not need historical revenue numbers.
B40: GAAP EBITDA | C40: 1800 | D40: 1900 | E40: 2000 | F40: =F41*F37 | G40: =G41*G37 | H40: =H41*H37 | I40: =I41*I37 | J40: =J41*J37 | L40: =_xlfn.RRI(2,C40,E40) | O40: *In the short/medium run, margins in ETA often decline and remain lower than historical margins (see research linked below for more). We rarely see a search fund business of scale with margins greater than 35%.
B41: Margin | C41: =C40/C37 | D41: =D40/D37 | E41: =E40/E37 | F41: 0.2 | G41: 0.25 | H41: 0.25 | I41: 0.3 | J41: 0.33 | O41: Research on EBITDA Margins in ETA - Thomas, Stevens, & Wasserstein
B43: GAAP EBITDA | F43: =F40 | G43: =G40 | H43: =H40 | I43: =I40 | J43: =J40
B44: Depreciation | F44: =-($L$44*F37) | G44: =-($L$44*G37) | H44: =-($L$44*H37) | I44: =-($L$44*I37) | J44: =-($L$44*J37) | L44: 0.01 | M44: % of Revenue | O44: *For asset-light search fund target businesses, depreciation will likely be minimal at around ~1-3% of revenue.
B45: EBIT | F45: =SUM(F43:F44) | G45: =SUM(G43:G44) | H45: =SUM(H43:H44) | I45: =SUM(I43:I44) | J45: =SUM(J43:J44)
B47: Interest | F47: =-F80-F89 | G47: =-G80-G89 | H47: =-H80-H89 | I47: =-I80-I89 | J47: =-J80-J89
B48: EBT | F48: =F45+F47 | G48: =G45+G47 | H48: =H45+H47 | I48: =I45+I47 | J48: =J45+J47
B50: Taxes Owed / Distributed | E50: =IF(N24="LLC",45%,26.5%) | F50: =-$E$50*F48 | G50: =-$E$50*G48 | H50: =-$E$50*H48 | I50: =-$E$50*I48 | J50: =-$E$50*J48
B51: Net Income | F51: =F48+F50 | G51: =G48+G50 | H51: =H48+H50 | I51: =I48+I50 | J51: =J48+J50
...
